Workbook
Name MmExcelLinker_8368C8B8_2491_440F_8D31_BFFF1753CA9A: Base_matières!#REF!
Name MmExcelLinker_E0A0798F_30E1_4931_84BD_B4AB4D3F1999: Parametres!$A$81:$X$81
Name Prix_frontal_au_m²: Base_matières!#REF!

Sheet Parametres
C1: Taux de change | G1: 0.85 | H1: Incidence dollar ou taxes | O1: Prix | S1: Transport | T1: USD | W1: 4000
C2: Prix Matières Premières | D2: Poids | E2: Poids en gsm | F2: Prix Ancien | G2: Fournisseur | H2: Prix en EUROS par m² | I2: Taxes ou Gaz | J2: Silicone + azote | K2: Incidence dollar ou taxes import | L2: Prix en DOLLARS au m² | N2: Prix au Kg en USD | O2: Prix au kg en USD | P2: Poids | Q2: Prix /m² | S2: Transport par 26,000 kg | T2: Transport au kg | U2: Transport au m² | W2: Conversion dollar - euro | X2: Poids au m² | Y2: Fournisseur | Z2: Appellation | AA2: Grammage
C3: 1- Silicone
A4: Linerless | C4: Sans silicone | H4: 0
A5: Linerless | C5: Linerless | H5: 0
A6: S | C6: Silicone Phoenix Release | G6: Phoenix | H6: =N6*X6 -> 0.0572 | N6: 28.6 | X6: 0.002 | Y6: Evonik
A7: S | C7: Silicone Phoenix Release + azote | G7: Phoenix | H7: =N7*X7 -> 0.0772 | N7: 38.6 | X7: 0.002 | Y7: Evonik
A9: SGLN | C9: Sans Glassine | H9: 0
A10: GLS | B10: 58 | C10: Glassine 58 g sil./Itasa Prix en Baisse | G10: Itasa | H10: 0.148 | Y10: Mondi | Z10: GLS | AA10: 62
A11: GLS | B11: 58 | C11: Glassine 58 g sil./Itasa KS2 (E) | D11: 46119 | F11: 0.155 | G11: Itasa | H11: 0.18 | Y11: Mondi | Z11: GLS | AA11: 62
A12: GLS | B12: 47 | C12: Glassine 58 g chinois SU | G12: Chine | H12: =L12*K12 -> 0.10423458 | K12: 0.92 | L12: =(O12+T12)*X12 -> 0.11329846 | O12: 1.696 | P12: 26000 | S12: 5000 | T12: =S12/P12 -> 0.19230769 | W12: 1 | X12: 0.06 | Y12: Mondi | Z12: GLS | AA12: 62
A13: GLS | B13: 47 | C13: Glassine 58 g chinois LK | F13: G1101 | G13: Chine | H13: =L13*K13 -> 0.11163138 | K13: 0.92 | L13: =(O13+T13)*X13 -> 0.12133846 | O13: 1.83 | P13: 26000 | S13: 5000 | T13: =S13/P13 -> 0.19230769 | W13: 1 | X13: 0.06 | Y13: Mondi | Z13: GLS | AA13: 62
C14: 3- Adhésif enlevable
A15: E | B15: 2355 | C15: 2355/22 | D15: au 07/04/26 | F15: 5.89 | G15: Bostik | H15: =N15*X15 -> 0.14881 | I15: 1 | N15: 6.47 | X15: 0.023 | Y15: Bostik | Z15: EN
A16: E | B16: 1408 | C16: 1408/22 | D16: 46119 | F16: 3.7 | G16: Meltavis | H16: =N16*X16 -> 0.0966 | N16: 4.2 | X16: 0.023 | Y16: Meltavis
C17: 5- Adhésif congélation | I17: 1
A18: E | B18: 2259 | C18: 2259/22 | D18: 46119 | F18: 5.35 | G18: Bostik | H18: =N18*X18 -> 0.13524 | I18: 1 | N18: 5.88 | X18: 0.023 | Y18: Bostik | Z18: CO
A19: P | B19: 2028 | C19: 2028/22 | G19: Jaour | H19: =N19*X19*K19 -> 0.075465 | K19: 1.075 | N19: 2.7 | X19: 0.026 | Y19: Jaour
A20: P | B20: 2028 | C20: 2028/25 | G20: Jaour | H20: =N20*X20*K20 -> 0.075465 | K20: 1.075 | N20: 2.7 | X20: 0.026 | Y20: Jaour
A21: P | B21: 2028 | C21: 2030/22 | G21: Jaour | H21: =N21*X21*K21 -> 0.07689475 | I21: 1.065 | K21: 1.075 | N21: 3.11 | X21: 0.023 | Y21: Jaour
A22: P | B22: 2028 | C22: 2028/30 | G22: Jaour | H22: =N22*X22*K22 -> 0.106984 | I22: 1.065 | K22: 1.075 | N22: 3.11 | X22: 0.032 | Y22: Jaour
A23: P | B23: P1503 | C23: P1503/22 | G23: Focus | H23: =N23*X23 -> 0.0726 | I23: 1.065 | N23: 3.3 | X23: 0.022 | Y23: Jaour
C24: 5- Adhésif permanent
A25: P | B25: 2028Y | C25: 2028Y/19 | D25: au 07/04/26 prix 2,36 € | G25: Jaour | H25: =N25*X25*K25 -> 0.058695 | I25: 1.065 | K25: 1.075 | N25: 2.73 | X25: 0.02 | Y25: Jaour
A26: P | B26: 2028Y | C26: 2028Y/22 | D26: au 07/04/26 prix 2,36 € | G26: Jaour | H26: =N26*X26*K26 -> 0.06749925 | I26: 1.065 | K26: 1.075 | N26: 2.73 | X26: 0.023 | Y26: Jaour
A27: P | B27: 2028Y | C27: 2028Y/25 | D27: au 07/04/26 prix 2,36 € | G27: Jaour | H27: =N27*X27*K27 -> 0.0763035 | I27: 1.065 | K27: 1.075 | N27: 2.73 | X27: 0.026 | Y27: Jaour
A28: P | B28: 2028Y | C28: 2028Y/40 | D28: au 07/04/26 prix 2,36 € | G28: Jaour | H28: =N28*X28*K28 -> 0.1232595 | I28: 1.065 | K28: 1.075 | N28: 2.73 | X28: 0.042 | Y28: Jaour
B29: P1201 | C29: P1201T/19 | G29: Focus | H29: =N29*X29 -> 0.0534 | N29: 2.67 | X29: 0.02 | Y29: Focus
B30: P1201 | C30: P1201T/22 | G30: Focus | H30: =N30*X30 -> 0.06141 | N30: 2.67 | X30: 0.023 | Y30: Focus
B31: P1203 | C31: P1203 | G31: Focus | H31: =N31*X31 -> 0.059 | N31: 2.95 | X31: 0.02 | Y31: Focus
C33: 5- Adhésif pneumatique
A34: P | B34: 2288 | C34: 2288/55 | G34: Jaour | H34: =(N34+T34)*X34 -> 0.16005 | K34: 1.075 | N34: 2.91 | P34: 26000 | X34: 0.055 | Y34: Jaour
A35: P | B35: 2288 | C35: 2288/25 | G35: Jaour | H35: =(N35+T35)*X35 -> 0.07566 | I35: 1.065 | K35: 1.075 | N35: 2.91 | X35: 0.026 | Y35: Jaour
A36: P | B36: 1401 | C36: 1401/55 | G36: Focus | H36: =N36*X36 -> 0.16995 | N36: 3.09 | X36: 0.055
C37: 6- Velin
A38: VB | B38: 70 | C38: Velin Etiwell 68 g | G38: Burgo | H38: =N38*X38 -> 0.08976 | N38: 1.32 | X38: 0.068 | Y38: UPM | Z38: VBS
A39: VB | B39: 70 | C39: Velin fluo guyenne | G39: Guyenne | H39: 0.28
C41: 6- Couché
A42: CO | B42: 80 | C42: Eti Lux 80 g Burgo | G42: Mosaico | H42: =N42*X42 -> 0.0888 | N42: 1.11 | X42: 0.08 | Z42: COS
A43: CO | B43: 115 | C43: Couché 115 grammes | H43: 0.15
...

Sheet Base_matières
B1: Désignation | C1: Frontal | D1: Type | E1: Adhésif | F1: Silicone | G1: Glassine | I1: COHESIO | J1: ROTOFLEX
A3: VELIN
A4: 1012 | B4: =CONCATENATE(C4," ",D4," ",E4," ",F4," ",G4) -> Velin Etiwell 68 g Permanent 2028Y/19 Sans silicone Glassine 58 g chinois LK | C4: Velin Etiwell 68 g | D4: Permanent | E4: 2028Y/19 | F4: Sans silicone | G4: Glassine 58 g chinois LK | I4: {=IF(B4="","",SUM(_xlfn._xlws.FILTER(Parametres!H$1:H$257, (Parametres!C$1:C$257=E4) + (Parametres!C$1:C$257=G4) + (Parametres!C$1:C$257=F4) + (Parametres!C$1:C$257=C4))))} -> 0.26008638 | J4: =I4+0.06 -> 0.32008638
A5: 1012 | B5: =CONCATENATE(C5," ",D5," ",E5," ",F5," ",G5) -> Velin Etiwell 68 g Permanent 2028Y/22 Sans silicone Glassine 58 g chinois LK | C5: Velin Etiwell 68 g | D5: Permanent | E5: 2028Y/22 | F5: Sans silicone | G5: Glassine 58 g chinois LK | H5: B | I5: {=IF(B5="","",SUM(_xlfn._xlws.FILTER(Parametres!H$1:H$257, (Parametres!C$1:C$257=E5) + (Parametres!C$1:C$257=G5) + (Parametres!C$1:C$257=F5) + (Parametres!C$1:C$257=C5))))} -> 0.26889063 | J5: =I5+0.06 -> 0.32889063
I6: {=IF(B6="","",SUM(_xlfn._xlws.FILTER(Parametres!H$1:H$257, (Parametres!C$1:C$257=E6) + (Parametres!C$1:C$257=G6) + (Parametres!C$1:C$257=F6) + (Parametres!C$1:C$257=C6))))}
A7: 1012 | B7: =CONCATENATE(C7," ",D7," ",E7," ",F7," ",G7) -> Velin Etiwell 68 g Enlevable 1408/22 Sans silicone Glassine 58 g chinois LK | C7: Velin Etiwell 68 g | D7: Enlevable | E7: 1408/22 | F7: Sans silicone | G7: Glassine 58 g chinois LK | H7: B | I7: {=IF(B7="","",SUM(_xlfn._xlws.FILTER(Parametres!H$1:H$257, (Parametres!C$1:C$257=E7) + (Parametres!C$1:C$257=G7) + (Parametres!C$1:C$257=F7) + (Parametres!C$1:C$257=C7))))} -> 0.29799138 | J7: =I7+0.06 -> 0.35799138
A8: 1012 | B8: =CONCATENATE(C8," ",D8," ",E8," ",F8," ",G8) -> Velin Etiwell 68 g Enlevable 2355/22 Sans silicone Glassine 58 g chinois LK | C8: Velin Etiwell 68 g | D8: Enlevable | E8: 2355/22 | F8: Sans silicone | G8: Glassine 58 g chinois LK | H8: B | I8: {=IF(B8="","",SUM(_xlfn._xlws.FILTER(Parametres!H$1:H$257, (Parametres!C$1:C$257=E8) + (Parametres!C$1:C$257=G8) + (Parametres!C$1:C$257=F8) + (Parametres!C$1:C$257=C8))))} -> 0.35020138 | J8: =I8+0.06 -> 0.41020138
I9: {=IF(B9="","",SUM(_xlfn._xlws.FILTER(Parametres!H$1:H$257, (Parametres!C$1:C$257=E9) + (Parametres!C$1:C$257=G9) + (Parametres!C$1:C$257=F9) + (Parametres!C$1:C$257=C9))))}
A10: 1012 | B10: =CONCATENATE(C10," ",D10," ",E10," ",F10," ",G10) -> Velin Etiwell 68 g Congélation 2030/22 Sans silicone Glassine 58 g chinois LK | C10: Velin Etiwell 68 g | D10: Congélation | E10: 2030/22 | F10: Sans silicone | G10: Glassine 58 g chinois LK | H10: B | I10: {=IF(B10="","",SUM(_xlfn._xlws.FILTER(Parametres!H$1:H$257, (Parametres!C$1:C$257=E10) + (Parametres!C$1:C$257=G10) + (Parametres!C$1:C$257=F10) + (Parametres!C$1:C$257=C10))))} -> 0.27828613 | J10: =I10+0.06 -> 0.33828613
A11: 1043 | B11: =CONCATENATE(C11," ",D11," ",E11," ",F11," ",G11) -> Velin Etiwell 68 g Congélation 2028/25 Sans silicone Glassine 58 g chinois LK | C11: Velin Etiwell 68 g | D11: Congélation | E11: 2028/25 | F11: Sans silicone | G11: Glassine 58 g chinois LK | H11: H | I11: {=IF(B11="","",SUM(_xlfn._xlws.FILTER(Parametres!H$1:H$257, (Parametres!C$1:C$257=E11) + (Parametres!C$1:C$257=G11) + (Parametres!C$1:C$257=F11) + (Parametres!C$1:C$257=C11))))} -> 0.27685638 | J11: =I11+0.06 -> 0.33685638
B12: =CONCATENATE(C12," ",D12," ",E12," ",F12," ",G12)
A13: 1012 | B13: =CONCATENATE(C13," ",D13," ",E13," ",F13," ",G13) -> Velin Etiwell 68 g Pneu 2288/25 Sans silicone Glassine 58 g chinois LK | C13: Velin Etiwell 68 g | D13: Pneu | E13: 2288/25 | F13: Sans silicone | G13: Glassine 58 g chinois LK | H13: B | I13: {=IF(B13="","",SUM(_xlfn._xlws.FILTER(Parametres!H$1:H$257, (Parametres!C$1:C$257=E13) + (Parametres!C$1:C$257=G13) + (Parametres!C$1:C$257=F13) + (Parametres!C$1:C$257=C13))))} -> 0.27705138 | J13: =I13+0.06 -> 0.33705138
A15: 2100 | B15: =CONCATENATE(C15," ",D15," ",E15," ",F15," ",G15) -> Velin fluo guyenne Permanent 2028Y/19 Sans Silicone Glassine 58 g chinois LK | C15: Velin fluo guyenne | D15: Permanent | E15: 2028Y/19 | F15: Sans Silicone | G15: Glassine 58 g chinois LK | I15: {=IF(B15="","",SUM(_xlfn._xlws.FILTER(Parametres!H$1:H$257, (Parametres!C$1:C$257=E15) + (Parametres!C$1:C$257=G15) + (Parametres!C$1:C$257=F15) + (Parametres!C$1:C$257=C15))))} -> 0.45032638 | J15: =I15+0.06 -> 0.51032638
I17: {=IF(B17="","",SUM(_xlfn._xlws.FILTER(Parametres!H$1:H$257, (Parametres!C$1:C$257=E17) + (Parametres!C$1:C$257=G17) + (Parametres!C$1:C$257=F17) + (Parametres!C$1:C$257=C17))))}
A18: COUCHE | I18: {=IF(B18="","",SUM(_xlfn._xlws.FILTER(Parametres!H$1:H$257, (Parametres!C$1:C$257=E18) + (Parametres!C$1:C$257=G18) + (Parametres!C$1:C$257=F18) + (Parametres!C$1:C$257=C18))))}
A19: 1141 | B19: =CONCATENATE(C19," ",D19," ",E19," ",F19," ",G19) -> Eti Lux 80 g Burgo Permanent 2028Y/19 Sans Silicone Glassine 58 g chinois | C19: Eti Lux 80 g Burgo | D19: Permanent | E19: 2028Y/19 | F19: Sans Silicone | G19: Glassine 58 g chinois | H19: B | I19: {=IF(B19="","",SUM(_xlfn._xlws.FILTER(Parametres!H$1:H$257, (Parametres!C$1:C$257=E19) + (Parametres!C$1:C$257=G19) + (Parametres!C$1:C$257=F19) + (Parametres!C$1:C$257=C19))))} -> 0.147495 | J19: =I19+0.06 -> 0.207495
I20: {=IF(B20="","",SUM(_xlfn._xlws.FILTER(Parametres!H$1:H$257, (Parametres!C$1:C$257=E20) + (Parametres!C$1:C$257=G20) + (Parametres!C$1:C$257=F20) + (Parametres!C$1:C$257=C20))))}
A21: 1141 | B21: =CONCATENATE(C21," ",D21," ",E21," ",F21," ",G21) -> Eti Lux 80 g Burgo Permanent 1408/22 Sans Silicone Glassine 58 g chinois | C21: Eti Lux 80 g Burgo | D21: Permanent | E21: 1408/22 | F21: Sans Silicone | G21: Glassine 58 g chinois | H21: B | I21: {=IF(B21="","",SUM(_xlfn._xlws.FILTER(Parametres!H$1:H$257, (Parametres!C$1:C$257=E21) + (Parametres!C$1:C$257=G21) + (Parametres!C$1:C$257=F21) + (Parametres!C$1:C$257=C21))))} -> 0.1854 | J21: =I21+0.06 -> 0.2454
A22: 1141 | B22: =CONCATENATE(C22," ",D22," ",E22," ",F22," ",G22) -> Eti Lux 80 g Burgo Permanent 2355/22 Sans Silicone Glassine 58 g chinois | C22: Eti Lux 80 g Burgo | D22: Permanent | E22: 2355/22 | F22: Sans Silicone | G22: Glassine 58 g chinois | H22: B | I22: {=IF(B22="","",SUM(_xlfn._xlws.FILTER(Parametres!H$1:H$257, (Parametres!C$1:C$257=E22) + (Parametres!C$1:C$257=G22) + (Parametres!C$1:C$257=F22) + (Parametres!C$1:C$257=C22))))} -> 0.23761 | J22: =I22+0.06 -> 0.29761
A24: 1141 | B24: =CONCATENATE(C24," ",D24," ",E24," ",F24," ",G24) -> Couché 115 grammes Permanent 2288/55 Sans Silicone Glassine 58 g chinois LK | C24: Couché 115 grammes | D24: Permanent | E24: 2288/55 | F24: Sans Silicone | G24: Glassine 58 g chinois LK | H24: B | I24: {=IF(B24="","",SUM(_xlfn._xlws.FILTER(Parametres!H$1:H$257, (Parametres!C$1:C$257=E24) + (Parametres!C$1:C$257=G24) + (Parametres!C$1:C$257=F24) + (Parametres!C$1:C$257=C24))))} -> 0.42168138 | J24: =I24+0.06 -> 0.48168138
A27: JET d'ENCRE | I27: {=IF(B27="","",SUM(_xlfn._xlws.FILTER(Parametres!H$1:H$257, (Parametres!C$1:C$257=E27) + (Parametres!C$1:C$257=G27) + (Parametres!C$1:C$257=F27) + (Parametres!C$1:C$257=C27))))}
B28: =CONCATENATE(C28," ",D28," ",E28," ",F28," ",G28) -> True color jet d'encre Permanent 2028Y/19 Sans Silicone Glassine 58 g chinois LK | C28: True color jet d'encre | D28: Permanent | E28: 2028Y/19 | F28: Sans Silicone | G28: Glassine 58 g chinois LK | H28: B | I28: {=IF(B28="","",SUM(_xlfn._xlws.FILTER(Parametres!H$1:H$257, (Parametres!C$1:C$257=E28) + (Parametres!C$1:C$257=G28) + (Parametres!C$1:C$257=F28) + (Parametres!C$1:C$257=C28))))} -> 0.41532638 | J28: =I28+0.06 -> 0.47532638
I29: {=IF(B29="","",SUM(_xlfn._xlws.FILTER(Parametres!H$1:H$257, (Parametres!C$1:C$257=E29) + (Parametres!C$1:C$257=G29) + (Parametres!C$1:C$257=F29) + (Parametres!C$1:C$257=C29))))}
A31: THERMIQUE ECO
I32: {=IF(B32="","",SUM(_xlfn._xlws.FILTER(Parametres!H$1:H$257, (Parametres!C$1:C$257=E32) + (Parametres!C$1:C$257=G32) + (Parametres!C$1:C$257=F32) + (Parametres!C$1:C$257=C32))))}
A33: 1012 | B33: =CONCATENATE(C33," ",D33," ",E33," ",F33," ",G33) -> Thermique Eco Chine Free lK Permanent 2028Y/19 Sans silicone Glassine 58 g chinois LK | C33: Thermique Eco Chine Free lK | D33: Permanent | E33: 2028Y/19 | F33: Sans silicone | G33: Glassine 58 g chinois LK | I33: {=IF(B33="","",SUM(_xlfn._xlws.FILTER(Parametres!H$1:H$257, (Parametres!C$1:C$257=E33) + (Parametres!C$1:C$257=G33) + (Parametres!C$1:C$257=F33) + (Parametres!C$1:C$257=C33))))} -> 0.2848494 | J33: 0.432
A34: 1012 | B34: =CONCATENATE(C34," ",D34," ",E34," ",F34," ",G34) -> Thermique Eco Chine Free lK Permanent 2028Y/22 Sans silicone Glassine 58 g chinois LK | C34: Thermique Eco Chine Free lK | D34: Permanent | E34: 2028Y/22 | F34: Sans silicone | G34: Glassine 58 g chinois LK | H34: B | I34: {=IF(B34="","",SUM(_xlfn._xlws.FILTER(Parametres!H$1:H$257, (Parametres!C$1:C$257=E34) + (Parametres!C$1:C$257=G34) + (Parametres!C$1:C$257=F34) + (Parametres!C$1:C$257=C34))))} -> 0.29365365 | J34: 0.432
I35: {=IF(B35="","",SUM(_xlfn._xlws.FILTER(Parametres!H$1:H$257, (Parametres!C$1:C$257=E35) + (Parametres!C$1:C$257=G35) + (Parametres!C$1:C$257=F35) + (Parametres!C$1:C$257=C35))))}
A36: 1012 | B36: =CONCATENATE(C36," ",D36," ",E36," ",F36," ",G36) -> Thermique Eco Chine Free lK Enlevable 1408/22 Sans silicone Glassine 58 g chinois LK | C36: Thermique Eco Chine Free lK | D36: Enlevable | E36: 1408/22 | F36: Sans silicone | G36: Glassine 58 g chinois LK | H36: B | I36: {=IF(B36="","",SUM(_xlfn._xlws.FILTER(Parametres!H$1:H$257, (Parametres!C$1:C$257=E36) + (Parametres!C$1:C$257=G36) + (Parametres!C$1:C$257=F36) + (Parametres!C$1:C$257=C36))))} -> 0.3227544 | J36: =I36+0.06 -> 0.3827544
A37: 1012 | B37: =CONCATENATE(C37," ",D37," ",E37," ",F37," ",G37) -> Thermique Eco Chine Free lK Enlevable 2355/22 Sans silicone Glassine 58 g chinois LK | C37: Thermique Eco Chine Free lK | D37: Enlevable | E37: 2355/22 | F37: Sans silicone | G37: Glassine 58 g chinois LK | H37: B | I37: {=IF(B37="","",SUM(_xlfn._xlws.FILTER(Parametres!H$1:H$257, (Parametres!C$1:C$257=E37) + (Parametres!C$1:C$257=G37) + (Parametres!C$1:C$257=F37) + (Parametres!C$1:C$257=C37))))} -> 0.3749644 | J37: =I37+0.06 -> 0.4349644
I38: {=IF(B38="","",SUM(_xlfn._xlws.FILTER(Parametres!H$1:H$257, (Parametres!C$1:C$257=E38) + (Parametres!C$1:C$257=G38) + (Parametres!C$1:C$257=F38) + (Parametres!C$1:C$257=C38))))}
A39: 1012 | B39: =CONCATENATE(C39," ",D39," ",E39," ",F39," ",G39) -> Thermique Eco Chine Free lK Congélation 2030/22 Sans silicone Glassine 58 g chinois LK | C39: Thermique Eco Chine Free lK | D39: Congélation | E39: 2030/22 | F39: Sans silicone | G39: Glassine 58 g chinois LK | H39: B | I39: {=IF(B39="","",SUM(_xlfn._xlws.FILTER(Parametres!H$1:H$257, (Parametres!C$1:C$257=E39) + (Parametres!C$1:C$257=G39) + (Parametres!C$1:C$257=F39) + (Parametres!C$1:C$257=C39))))} -> 0.30304915 | J39: =I39+0.06 -> 0.36304915
A40: 1043 | B40: =CONCATENATE(C40," ",D40," ",E40," ",F40," ",G40) -> Thermique Eco Chine Free lK Congélation 2028/25 Sans silicone Glassine 58 g chinois LK | C40: Thermique Eco Chine Free lK | D40: Congélation | E40: 2028/25 | F40: Sans silicone | G40: Glassine 58 g chinois LK | H40: H | I40: {=IF(B40="","",SUM(_xlfn._xlws.FILTER(Parametres!H$1:H$257, (Parametres!C$1:C$257=E40) + (Parametres!C$1:C$257=G40) + (Parametres!C$1:C$257=F40) + (Parametres!C$1:C$257=C40))))} -> 0.3016194 | J40: =I40+0.06 -> 0.3616194
B41: =CONCATENATE(C41," ",D41," ",E41," ",F41," ",G41)
A42: 1012 | B42: =CONCATENATE(C42," ",D42," ",E42," ",F42," ",G42) -> Thermique Eco Chine Free lK Pneu 2288/25 Sans silicone Glassine 58 g chinois LK | C42: Thermique Eco Chine Free lK | D42: Pneu | E42: 2288/25 | F42: Sans silicone | G42: Glassine 58 g chinois LK | H42: B
I43: {=IF(B43="","",SUM(_xlfn._xlws.FILTER(Parametres!H$1:H$257, (Parametres!C$1:C$257=E43) + (Parametres!C$1:C$257=G43) + (Parametres!C$1:C$257=F43) + (Parametres!C$1:C$257=C43))))}
I44: {=IF(B44="","",SUM(_xlfn._xlws.FILTER(Parametres!H$1:H$257, (Parametres!C$1:C$257=E44) + (Parametres!C$1:C$257=G44) + (Parametres!C$1:C$257=F44) + (Parametres!C$1:C$257=C44))))}
A45: THERMIQUE PRO | I45: {=IF(B45="","",SUM(_xlfn._xlws.FILTER(Parametres!H$1:H$257, (Parametres!C$1:C$257=E45) + (Parametres!C$1:C$257=G45) + (Parametres!C$1:C$257=F45) + (Parametres!C$1:C$257=C45))))}
I46: {=IF(B46="","",SUM(_xlfn._xlws.FILTER(Parametres!H$1:H$257, (Parametres!C$1:C$257=E46) + (Parametres!C$1:C$257=G46) + (Parametres!C$1:C$257=F46) + (Parametres!C$1:C$257=C46))))}
A47: 1012 | B47: =CONCATENATE(C47," ",D47," ",E47," ",F47," ",G47) -> Thermique Top Chine Free lK Permanent 2028Y/19 Sans silicone Glassine 58 g chinois LK | C47: Thermique Top Chine Free lK | D47: Permanent | E47: 2028Y/19 | F47: Sans silicone | G47: Glassine 58 g chinois LK | I47: {=IF(B47="","",SUM(_xlfn._xlws.FILTER(Parametres!H$1:H$257, (Parametres!C$1:C$257=E47) + (Parametres!C$1:C$257=G47) + (Parametres!C$1:C$257=F47) + (Parametres!C$1:C$257=C47))))} -> 0.301207 | J47: =I47+0.06 -> 0.361207
...
